Workbook

Sheet Summary
A1: Nexus QA Checklist — Summary
A2: App | B2: Pass | C2: Fail | D2: Total
A3: Sheets | B3: =COUNTIF(Sheets!E2:E300,"Pass") | C3: =COUNTIF(Sheets!E2:E300,"Fail") | D3: =COUNTA(Sheets!A2:A300)
A4: Slides | B4: =COUNTIF(Slides!E2:E300,"Pass") | C4: =COUNTIF(Slides!E2:E300,"Fail") | D4: =COUNTA(Slides!A2:A300)
A5: Docs | B5: =COUNTIF(Docs!E2:E300,"Pass") | C5: =COUNTIF(Docs!E2:E300,"Fail") | D5: =COUNTA(Docs!A2:A300)
A6: Notes | B6: =COUNTIF(Notes!E2:E300,"Pass") | C6: =COUNTIF(Notes!E2:E300,"Fail") | D6: =COUNTA(Notes!A2:A300)
A7: Drive | B7: =COUNTIF(Drive!E2:E300,"Pass") | C7: =COUNTIF(Drive!E2:E300,"Fail") | D7: =COUNTA(Drive!A2:A300)
A8: Navigation | B8: =COUNTIF(Navigation!E2:E300,"Pass") | C8: =COUNTIF(Navigation!E2:E300,"Fail") | D8: =COUNTA(Navigation!A2:A300)
A9: HR & Mentor | B9: =COUNTIF('HR & Mentor'!E2:E300,"Pass") | C9: =COUNTIF('HR & Mentor'!E2:E300,"Fail") | D9: =COUNTA('HR & Mentor'!A2:A300)
A10: TOTAL | B10: =SUM(B3:B9) | C10: =SUM(C3:C9) | D10: =SUM(D3:D9)

Sheet Sheets
A1: # | B1: Feature | C1: How to test | D1: Expected result | E1: Status | F1: Notes
A2: 1 | B2: Cell selection (single) | C2: Click any cell | D2: Cell highlighted with blue border | E2: Not tested
A3: 2 | B3: Cell editing | C3: Double-click or type to enter edit mode | D3: Input appears in cell | E3: Not tested
A4: 3 | B4: Formula bar | C4: Enter =SUM(A1:A3) | D4: Result computed and shown | E4: Not tested
A5: 4 | B5: Arrow key navigation | C5: Arrow keys move selection | D5: Selection moves correctly | E5: Not tested
A6: 5 | B6: Tab / Enter navigation | C6: Tab moves right, Enter moves down | D6: Correct navigation | E6: Not tested
A7: 6 | B7: Drag-to-select range | C7: Mouse-down on A1, drag to D5 | D7: A1:D5 highlighted (FIXED) | E7: Not tested
A8: 7 | B8: Fill handle — copy | C8: Select 'hello', drag fill handle down | D8: hello copied to each cell | E8: Not tested
A9: 8 | B9: Fill handle — series | C9: Select 1,2,3,4 (multi-cell), drag down | D9: 5,6,7,8... continues (FIXED) | E9: Not tested
A10: 9 | B10: Shift+click range | C10: Click A1, shift+click E10 | D10: A1:E10 selected | E10: Not tested
A11: 10 | B11: Ctrl+C / Ctrl+V | C11: Copy range, paste elsewhere | D11: TSV paste works | E11: Not tested
A12: 11 | B12: Ctrl+X cut | C12: Cut range, paste elsewhere | D12: Source cleared, pasted elsewhere | E12: Not tested
A13: 12 | B13: Ctrl+B/I/U bold/italic/underline | C13: Select cell, press Ctrl+B | D13: Style applied | E13: Not tested
... A16: 15 | B16: Rename sheet | C16: Double-click tab | D16: Rename input appears | E16: Not tested
A17: 16 | B17: Named ranges | C17: Toolbar > Named Ranges, define A1:B5=myRange, use in formula | D17: =SUM(myRange) evaluates | E17: Not tested
A18: 17 | B18: Data validation dropdown | C18: Set dropdown list for a cell | D18: ▾ appears, only allowed values accepted | E18: Not tested
A19: 18 | B19: Conditional formatting | C19: Select range, add rule GT 50 → green fill | D19: Cells > 50 turn green | E19: Not tested
A20: 19 | B20: Conditional formatting manage rules | C20: Open CF dialog, see existing rules, delete one | D20: Rule removed | E20: Not tested
A21: 20 | B21: F4 absolute ref | C21: Type =A1 in formula bar, press F4 | D21: Cycles $A$1 → A$1 → $A1 → A1 | E21: Not tested
A22: 21 | B22: Sort A→Z from right-click | C22: Right-click column, Sort A→Z | D22: Column sorted ascending | E22: Not tested
A23: 22 | B23: Filter | C23: Click Filter toolbar btn, filter a column | D23: Only matching rows shown | E23: Not tested
A24: 23 | B24: Freeze panes | C24: Freeze 2 rows — scroll down | D24: Rows 1-2 stay fixed | E24: Not tested
A25: 24 | B25: Merge cells | C25: Select A1:C1, right-click Merge | D25: Cells merged | E25: Not tested
A26: 25 | B26: Pivot table | C26: Insert > Pivot on data range | D26: Pivot table rendered | E26: Not tested
A27: 26 | B27: Chart insert | C27: Select data, insert chart | D27: Chart rendered in sheet | E27: Not tested
A28: 27 | B28: Donut / radar / combo chart | C28: Change chart type | D28: Chart updates | E28: Not tested
A29: 28 | B29: Find & Replace (Ctrl+H) | C29: Open F&R, replace 'hello' with 'world' | D29: All instances replaced | E29: Not tested
... A36: 35 | B36: Number formats — $/%/1000 | C36: Quick format buttons in toolbar | D36: Format applied to cell | E36: Not tested
A37: 36 | B37: IFERROR formula | C37: =IFERROR(1/0,"err") | D37: Returns 'err' not #DIV/0! | E37: Not tested
A38: 37 | B38: TRIM / LEN / FIND | C38: =TRIM(' hi '), =LEN('abc'), =FIND('b','abc') | D38: hi, 3, 2 | E38: Not tested
A39: 38 | B39: TODAY() / YEAR() | C39: =TODAY() and =YEAR(TODAY()) | D39: Current date and year | E39: Not tested
A40: 39 | B40: Right-click context menu | C40: Right-click cell | D40: Menu: cut/copy/paste/insert row/col/etc | E40: Not tested
A41: 40 | B41: Sheet protection | C41: Right-click Protect sheet | D41: Cells locked from editing | E41: Not tested
A42: 41 | B42: Slide sorter view | C42: Sorter toggle btn | D42: All slides shown in grid | E42: Not tested
A43: 42 | B43: Slicers | C43: Right-click, Insert slicer | D43: Filter chips appear, click to filter | E43: Not tested
A44: 43 | B44: Pivot charts | C44: Toggle pivot to chart view | D44: BarChart rendered from pivot data | E44: Not tested
A45: Sheets | B45: Spill Formulas | C45: =SEQUENCE(5,3) spills 5x3 grid of numbers | D45: Spill / array formulas | E45: —
A46: Sheets | B46: Spill Formulas | C46: =FILTER(range, condition) returns matching rows | D46: Spill / array formulas | E46: —
A47: Sheets | B47: Spill Formulas | C47: =UNIQUE(range) deduplicates and spills results | D47: Spill / array formulas | E47: —
A48: Sheets | B48: Spill Formulas | C48: =SORT(range) returns sorted column/array | D48: Spill / array formulas | E48: —
...

Sheet Slides
A1: # | B1: Feature | C1: How to test | D1: Expected result | E1: Status | F1: Notes
A2: 1 | B2: Add slide | C2: Click + New Slide | D2: Blank slide added | E2: Not tested
A3: 2 | B3: Add text box | C3: Click Text btn | D3: Text box appears on canvas | E3: Not tested
A4: 3 | B4: Edit text | C4: Double-click text element | D4: Inline text editing | E4: Not tested
A5: 4 | B5: Add shape | C5: Toolbar shape picker | D5: Shape rendered on canvas | E5: Not tested
A6: 5 | B6: Add image (upload) | C6: Image btn → pick file | D6: Image inserted | E6: Not tested
A7: 6 | B7: Resize element | C7: Drag corner handle | D7: Element resizes | E7: Not tested
A8: 7 | B8: Move element | C8: Drag element body | D8: Element moves | E8: Not tested
A9: 8 | B9: Delete element | C9: Select + Delete key | D9: Element removed | E9: Not tested
A10: 9 | B10: Entrance animation | C10: Select element, pick animation | D10: Animation plays in presenter | E10: Not tested
A11: 10 | B11: Slide transition | C11: Pick transition from dropdown | D11: Transition plays between slides | E11: Not tested
A12: 11 | B12: Present mode | C12: Click Present btn | D12: Full-screen presenter opens | E12: Not tested
A13: 12 | B13: Speaker notes — edit | C13: Type in notes area below canvas | D13: Notes saved with slide | E13: Not tested
... A36: 35 | B36: Audio element | C36: Insert audio | D36: Audio player rendered on slide | E36: Not tested
A37: Slides | B37: Keyboard Shortcuts | C37: Ctrl/Cmd+B toggles bold on selected text element | D37: Keyboard shortcuts | E37: —
A38: Slides | B38: Keyboard Shortcuts | C38: Ctrl/Cmd+I toggles italic on selected text element | D38: Keyboard shortcuts | E38: —
A39: Slides | B39: Keyboard Shortcuts | C39: Ctrl/Cmd+U toggles underline on selected text element | D39: Keyboard shortcuts | E39: —
A40: 1 | B40: PPTX import - real parse | C40: Import a real .pptx made in PowerPoint | D40: Slides appear with actual text, not a placeholder | E40: Not tested
A41: 2 | B41: PPTX import - positions | C41: Compare imported slide against the original | D41: Text boxes land in roughly the same positions | E41: Not tested
A42: 3 | B42: PPTX import - images | C42: Import a deck containing photos | D42: Images render on the imported slides | E42: Not tested
A43: 4 | B43: PPTX import - tables | C43: Import a deck containing a table | D43: Table appears with its rows and columns | E43: Not tested
A44: 5 | B44: PPTX import - notes | C44: Import a deck with speaker notes; open the notes panel | D44: Speaker notes carried across | E44: Not tested
A45: 6 | B45: PPTX import is additive | C45: Import into a deck that already has slides | D45: Existing slides kept; imported ones appended | E45: Not tested
A46: 7 | B46: PPTX import - bad file | C46: Try importing a .txt renamed to .pptx | D46: Clear error toast; editor not broken | E46: Not tested
A47: 8 | B47: Live co-editor presence | C47: Open the same deck as two users | D47: Avatar stack shows the other editor | E47: Not tested
A48: 9 | B48: Peer slide indicator | C48: Hover a peer's avatar while they view slide 3 | D48: Tooltip reads 'Name - Slide 3' | E48: Not tested
A49: 10 | B49: Version history + restore | C49: Edit, open history, restore an earlier version | D49: Deck reverts; 'Before restore' row created | E49: Not tested

Sheet Docs
A1: # | B1: Feature | C1: How to test | D1: Expected result | E1: Status | F1: Notes
A2: 1 | B2: Create new doc | C2: Click New Document | D2: Blank Tiptap editor opens | E2: Not tested
A3: 2 | B3: Type and save | C3: Type text, wait 2s | D3: Auto-saved (title appears in list) | E3: Not tested
A4: 3 | B4: Bold / Italic / Underline | C4: Select text, Ctrl+B/I/U | D4: Formatting applied | E4: Not tested
A5: 4 | B5: Font family picker | C5: Change font from toolbar | D5: Font applied to selected text | E5: Not tested
A6: 5 | B6: Font size picker | C6: Change size | D6: Size applied | E6: Not tested
A7: 6 | B7: Text color | C7: Pick color from toolbar | D7: Color applied | E7: Not tested
A8: 7 | B8: Highlight | C8: Pick highlight color | D8: Background highlight applied | E8: Not tested
A9: 8 | B9: Superscript / Subscript | C9: Toolbar btns | D9: Super/subscript applied | E9: Not tested
A10: 9 | B10: Heading styles | C10: H1/H2/H3 picker | D10: Heading applied | E10: Not tested
A11: 10 | B11: Bullet list | C11: Bullet btn | D11: List created | E11: Not tested
A12: 11 | B12: Numbered list | C12: Number btn | D12: Ordered list created | E12: Not tested
A13: 12 | B13: Checklist | C13: Checklist btn | D13: Interactive checklist rendered | E13: Not tested
... A33: 32 | B33: Share doc | C33: Share btn (if available) | D33: Share dialog opens | E33: Not tested
A34: Docs | B34: Track Changes | C34: Enable suggesting mode via 'Suggest' button in toolbar | D34: Track changes / suggest mode | E34: —
A35: Docs | B35: Track Changes | C35: Type text in suggesting mode — appears green underlined | D35: Track changes / suggest mode | E35: —
A36: Docs | B36: Track Changes | C36: Delete text in suggesting mode — text stays with red strikethrough | D36: Track changes / suggest mode | E36: —
A37: Docs | B37: Track Changes | C37: Suggestions panel shows list of insertions and deletions | D37: Track changes / suggest mode | E37: —
A38: Docs | B38: Track Changes | C38: Accept individual suggestion — insertion keeps, deletion removes | D38: Track changes / suggest mode | E38: —
A39: Docs | B39: Track Changes | C39: Reject individual suggestion — insertion removes, deletion keeps | D39: Track changes / suggest mode | E39: —
A40: Docs | B40: Track Changes | C40: Accept all suggestions clears all tracked marks | D40: Track changes / suggest mode | E40: —
A41: Docs | B41: Track Changes | C41: Reject all suggestions reverts all pending changes | D41: Track changes / suggest mode | E41: —
A42: Docs | B42: Track Changes | C42: Toggling suggest mode off exits suggesting but keeps marks pending | D42: Track changes / suggest mode | E42: —
A43: Docs | B43: Track Changes | C43: Suggesting mode banner visible in suggestions panel | D43: Track changes / suggest mode | E43: —
A44: 1 | B44: Export to Word (.docx) | C44: Export menu > Microsoft Word (.docx) | D44: File downloads and OPENS in Word without a repair warning | E44: Not tested
A45: 2 | B45: DOCX keeps headings | C45: Export a doc with H1/H2/H3, open in Word | D45: Heading styles preserved, not flattened to body text | E45: Not tested
A46: 3 | B46: DOCX keeps bold/italic | C46: Export text with bold, italic, underline | D46: Formatting preserved in Word | E46: Not tested
A47: 4 | B47: DOCX keeps lists | C47: Export bulleted and numbered lists incl. nesting | D47: Lists render as real Word lists | E47: Not tested
A48: 5 | B48: DOCX keeps tables | C48: Export a doc containing a table | D48: Table renders with borders in Word | E48: Not tested
A49: 6 | B49: DOCX keeps links | C49: Export a doc with a hyperlink | D49: Link is clickable in Word | E49: Not tested
A50: 7 | B50: DOCX keeps images | C50: Insert an uploaded image, export, open in Word | D50: Image embedded in the .docx | E50: Not tested
A51: 8 | B51: Import Word (.docx) | C51: Export menu > Import Word (.docx) | D51: Content appended into the editor | E51: Not tested
A52: 9 | B52: Import names untitled doc | C52: Import into an Untitled document | D52: Doc title becomes the filename | E52: Not tested
A53: 10 | B53: Import is additive | C53: Import into a doc with existing text | D53: Existing text kept, imported content appended | E53: Not tested
A54: 11 | B54: Versions are server-side | C54: Save a version, then open the doc in a different browser | D54: Same version list appears (was localStorage-only before) | E54: Not tested
A55: 12 | B55: Version restore | C55: Restore an older version | D55: Editor reloads it; 'Before restore' row created | E55: Not tested

Sheet Notes
A1: # | B1: Feature | C1: How to test | D1: Expected result | E1: Status | F1: Notes
A2: 1 | B2: Create note | C2: Click New Note | D2: Blank note created | E2: Not tested
A3: 2 | B3: Type & auto-save | C3: Type in editor | D3: Note auto-saves | E3: Not tested
A4: 3 | B4: Pin note | C4: Pin icon on note card | D4: Note moves to Pinned section | E4: Not tested
A5: 4 | B5: Color note | C5: Palette icon | D5: Note card color changes | E5: Not tested
A6: 5 | B6: Delete note | C6: Delete btn | D6: Note removed | E6: Not tested
A7: 6 | B7: Search notes | C7: Search bar | D7: Filtered note list | E7: Not tested
A8: 7 | B8: Folder filter | C8: Click folder in sidebar | D8: Only notes in that folder shown | E8: Not tested
A9: 8 | B9: Note tags — add | C9: Type tag in tag input, press Enter | D9: Tag chip appears on note | E9: Not tested
A10: 9 | B10: Note tags — remove | C10: Click × on tag chip | D10: Tag removed | E10: Not tested
A11: 10 | B11: Note tags — filter by tag | C11: Click tag in sidebar Tags section | D11: Only tagged notes shown | E11: Not tested
A12: 11 | B12: Tag chip in note list | C12: Note with tags in list view | D12: First 2 tags shown as chips | E12: Not tested
A13: 12 | B13: Note templates | C13: Template picker on new note | D13: Meeting/To-do/Journal pre-filled | E13: Not tested
... A33: 32 | B33: Legacy tags still show | C33: Open a note tagged before the migration | D33: Its old tags still render | E33: Not tested

Sheet Drive
A1: # | B1: Feature | C1: How to test | D1: Expected result | E1: Status | F1: Notes
A2: 1 | B2: Upload file | C2: Click Upload / drag-drop | D2: File appears in Drive | E2: Not tested
A3: 2 | B3: Create folder | C3: New > Folder | D3: Folder created | E3: Not tested
A4: 3 | B4: Download file | C4: Download btn on file | D4: File downloads | E4: Not tested
A5: 4 | B5: Delete file | C5: Delete btn | D5: File moved to trash or deleted | E5: Not tested
A6: 5 | B6: Grid / list view toggle | C6: Toggle btn | D6: View switches | E6: Not tested
A7: 6 | B7: Search files | C7: Search bar | D7: Files filtered by name | E7: Not tested
A8: 7 | B8: Star/unstar file | C8: Star icon | D8: File starred; Starred filter shows it | E8: Not tested
A9: 8 | B9: Multi-select files | C9: Checkbox or Ctrl+click | D9: Bulk action bar appears | E9: Not tested
A10: 9 | B10: Bulk delete | C10: Select multiple, Delete | D10: All deleted | E10: Not tested
A11: 10 | B11: Move file (drag-drop) | C11: Drag file to folder | D11: File moved into folder | E11: Not tested
A12: 11 | B12: Breadcrumb navigation | C12: Click folder in breadcrumb | D12: Navigate up the tree | E12: Not tested
A13: 12 | B13: Storage meter | C13: Check left sidebar | D13: Storage usage shown | E13: Not tested
... A18: 17 | B18: Search filters | C18: Type + file type filter | D18: Results narrowed | E18: Not tested

Sheet Navigation
A1: # | B1: Feature | C1: How to test | D1: Expected result | E1: Status | F1: Notes
A2: 1 | B2: Sidebar nav — all items | C2: Click each nav item | D2: Each page loads without 403 | E2: Not tested
A3: 2 | B3: Full-screen editor (Sheets) | C3: Open a Sheet | D3: No portal sidebar shown | E3: Not tested
A4: 3 | B4: Full-screen editor (Slides) | C4: Open a Slide deck | D4: No portal sidebar shown | E4: Not tested
A5: 4 | B5: Full-screen editor (Docs) | C5: Open a Doc | D5: No portal sidebar shown | E5: Not tested
A6: 5 | B6: Back to Apps from Sheets list | C6: /apps/sheets — Back btn | D6: Returns to /apps | E6: Not tested
A7: 6 | B7: Back to Apps from Slides list | C7: /apps/slides — Back btn | D7: Returns to /apps | E7: Not tested
A8: 7 | B8: Back btn inside Sheet editor | C8: ← btn in title bar | D8: Returns to /apps/sheets | E8: Not tested
A9: 8 | B9: Back btn inside Slides editor | C9: ← btn in title bar | D9: Returns to /apps/slides | E9: Not tested
A10: 9 | B10: Back btn in Docs sidebar | C10: ← All Docs link | D10: Returns to /apps | E10: Not tested
A11: 10 | B11: Role-based access | C11: Login as different roles | D11: Correct nav items shown per role | E11: Not tested
A12: 11 | B12: 404 / 403 handling | C12: Visit unknown path | D12: Appropriate error page | E12: Not tested
A13: 12 | B13: Login redirect | C13: Visit /inbox unauthenticated | D13: Redirected to /login | E13: Not tested
... A31: 30 | B31: API calls same-origin | C31: On docs.cybersage.uk open devtools Network | D31: /api/* requests return 200, not 404 | E31: Not tested

Sheet HR & Mentor
A1: # | B1: Feature | C1: How to test | D1: Expected result | E1: Status | F1: Notes
A2: HR | B2: My HR page | C2: Open /hr as any role | D2: Leave balances, request form, holidays, documents, onboarding visible | E2: —
A3: HR | B3: Leave request | C3: Submit annual leave with valid dates | D3: Request created, appears as pending; managers get notification | E3: —
A4: HR | B4: Leave balance guard | C4: Request more days than remaining allowance | D4: 400 error with 'insufficient balance' toast | E4: —
A5: HR | B5: Leave overlap guard | C5: Submit a second request overlapping the first | D5: 409 'overlaps existing request' | E5: —
A6: HR | B6: Leave approval | C6: Admin /admin/hr?tab=leave → Approve | D6: Status APPROVED; requester notified; balance reduces | E6: —
A7: HR | B7: Leave rejection | C7: Reject with a note | D7: Status REJECTED, note visible to requester on /hr | E7: —
A8: HR | B8: Cancel leave | C8: Requester cancels own pending request | D8: Status CANCELLED | E8: —
A9: HR | B9: Holidays | C9: Admin adds a holiday; request leave spanning it | D9: Holiday excluded from working-day count | E9: —
A10: HR | B10: HR dashboard | C10: Open /admin/hr Dashboard tab | D10: Headcounts, pending leave, on-leave-today, dept chart render | E10: —
A11: HR | B11: HR documents (admin) | C11: People tab → expand person → upload contract | D11: Doc listed with category; download returns file via signed URL | E11: —
A12: HR | B12: HR documents (self) | C12: Upload own doc on /hr; try downloading another user's doc id | D12: Own doc works; foreign doc returns 403 | E12: —
A13: HR | B13: Onboarding template | C13: Expand person → Apply default checklist | D13: 7 items created; toggling marks complete; progress shows on user's /hr | E13: —
... A23: Intern | B23: Certificate print | C23: Click Print / PDF on a certificate | D23: Printable landscape certificate opens with name, serial, grade | E23: —
